<?xml version="1.0"?>
<robot xmlns:xacro="http://www.ros.org/wiki/xacro" name="ugv">

   <xacro:macro name="wheel_link" params="name">
    <link name="${name}">
      <visual>
        <geometry>
          <cylinder radius="0.15" length="0.08"/>
        </geometry>
        <origin xyz="0 0 0" rpy="0 1.5708 0"/>
        <material name="Black">
          <color rgba="0.1 0.1 0.1 1"/>
        </material>
      </visual>
      <collision>
        <geometry>
          <cylinder radius="0.15" length="0.08"/>
        </geometry>
        <origin xyz="0 0 0" rpy="0 1.5708 0"/>
      </collision>
      <inertial>
        <mass value="5"/>
        <origin xyz="0 0 0"/>
        <inertia ixx="0.1" iyy="0.1" izz="0.2" ixy="0" ixz="0" iyz="0"/>
      </inertial>
    </link>
  </xacro:macro>

  <link name="base_footprint" />

  <link name="base_link">
    <visual>
      <geometry>
        <box size="1.8 1.0 0.8"/>
      </geometry>
      <material name="ChassisColor">
        <color rgba="0.5 0.5 0.5 1"/>
      </material>
    </visual>
    <collision>
      <geometry>
        <box size="1.8 1.0 0.8"/>
      </geometry>
    </collision>
    <inertial>
      <mass value="120"/>
      <origin xyz="0 0 0"/>
      <inertia ixx="12" iyy="12" izz="20" ixy="0" ixz="0" iyz="0"/>
    </inertial>
  </link>

  <!-- Generate wheel links -->
  <xacro:wheel_link name="wheel_left_0"/>
  <xacro:wheel_link name="wheel_left_1"/>
  <xacro:wheel_link name="wheel_left_2"/>
  <xacro:wheel_link name="wheel_right_0"/>
  <xacro:wheel_link name="wheel_right_1"/>
  <xacro:wheel_link name="wheel_right_2"/>

  <link name="lidar_front">
  <visual>
    <geometry>
      <cylinder radius="0.07" length="0.08"/>
    </geometry>
    <material name="Blue">
      <color rgba="0.1 0.3 0.8 1"/>
    </material>
  </visual>
  <collision>
    <geometry>
      <cylinder radius="0.07" length="0.08"/>
    </geometry>
  </collision>
  <inertial>
    <mass value="0.1"/>
    <origin xyz="0 0 0"/>
    <inertia ixx="1e-5" iyy="1e-5" izz="1e-5" ixy="0" ixz="0" iyz="0"/>
  </inertial>
</link>

<link name="lidar_back">
  <visual>
    <geometry>
      <cylinder radius="0.07" length="0.08"/>
    </geometry>
    <material name="Blue">
      <color rgba="0.1 0.3 0.8 1"/>
    </material>
  </visual>
  <collision>
    <geometry>
      <cylinder radius="0.07" length="0.08"/>
    </geometry>
  </collision>
  <inertial>
    <mass value="0.1"/>
    <origin xyz="0 0 0"/>
    <inertia ixx="1e-5" iyy="1e-5" izz="1e-5" ixy="0" ixz="0" iyz="0"/>
  </inertial>
</link>


  <link name="camera_front">
    <visual>
      <geometry>
        <box size="0.09 0.07 0.08"/>
      </geometry>
      <material name="Green">
        <color rgba="0.1 0.7 0.1 1"/>
      </material>
    </visual>
  </link>

  <link name="camera_back">
    <visual>
      <geometry>
        <box size="0.09 0.07 0.08"/>
      </geometry>
      <material name="Green">
        <color rgba="0.1 0.7 0.1 1"/>
      </material>
    </visual>
  </link>

  <!-- Joints -->
  <joint name="base_joint" type="fixed">
    <parent link="base_footprint"/>
    <child link="base_link"/>
    <origin xyz="0 0 0" rpy="0 0 0"/>
    <axis xyz="0 0 0"/>
  </joint>

  <joint name="joint_wheel_left_0" type="continuous">
    <parent link="base_link"/>
    <child link="wheel_left_0"/>
    <origin xyz="-0.8 -0.55 -0.35" rpy="0 0 1.57"/>
    <axis xyz="1 0 0"/>
  </joint>
  <joint name="joint_wheel_left_1" type="continuous">
    <parent link="base_link"/>
    <child link="wheel_left_1"/>
    <origin xyz="0 -0.55 -0.35" rpy="0 0 1.57"/>
    <axis xyz="1 0 0"/>
  </joint>
  <joint name="joint_wheel_left_2" type="continuous">
    <parent link="base_link"/>
    <child link="wheel_left_2"/>
    <origin xyz="0.8 -0.55 -0.35" rpy="0 0 1.57"/>
    <axis xyz="1 0 0"/>
  </joint>
  <joint name="joint_wheel_right_0" type="continuous">
    <parent link="base_link"/>
    <child link="wheel_right_0"/>
    <origin xyz="0.8 0.55 -0.35" rpy="0 0 1.57"/>
    <axis xyz="1 0 0"/>
  </joint>
  <joint name="joint_wheel_right_1" type="continuous">
    <parent link="base_link"/>
    <child link="wheel_right_1"/>
    <origin xyz="0 0.55 -0.35" rpy="0 0 1.57"/>
    <axis xyz="1 0 0"/>
  </joint>
  <joint name="joint_wheel_right_2" type="continuous">
    <parent link="base_link"/>
    <child link="wheel_right_2"/>
    <origin xyz="-0.8 0.55 -0.35" rpy="0 0 1.57"/>
    <axis xyz="1 0 0"/>
  </joint>

  <joint name="joint_lidar_front" type="fixed">
    <parent link="base_link"/>
    <child link="lidar_front"/>
    <origin xyz="0.82 0 0.44" rpy="0 0 0"/>
  </joint>

  <joint name="joint_lidar_back" type="fixed">
    <parent link="base_link"/>
    <child link="lidar_back"/>
    <origin xyz="-0.82 0 0.44" rpy="0 0 3.14159"/>
  </joint>
  <joint name="joint_camera_front" type="fixed">
    <parent link="base_link"/>
    <child link="camera_front"/>
    <origin xyz="0.75 0.14 0.44" rpy="0 0 0"/>
  </joint>
  <joint name="joint_camera_back" type="fixed">
    <parent link="base_link"/>
    <child link="camera_back"/>
    <origin xyz="-0.75 -0.14 0.44" rpy="0 0 3.14159"/> 
  </joint>
  
   <gazebo reference="camera_front">
        <material>Gazebo/Red</material>
        <sensor name="camera_sensor" type="camera">
            <pose>0 0 0 0 0 0</pose>
            <visualize>true</visualize>
            <update_rate>10.0</update_rate>
            <plugin name="camera_controller_front" filename="libgazebo_ros_camera.so">
                <frame_name>camera_front</frame_name>
                <image_topic_name>image_raw</image_topic_name>
            </plugin>
        </sensor>
    </gazebo>
  
  <gazebo reference="camera_back">
        <material>Gazebo/Red</material>
        <sensor name="camera_sensor" type="camera">
            <pose>0 0 0 0 0 0</pose>
            <visualize>true</visualize>
            <update_rate>10.0</update_rate>
            <plugin name="camera_controller_rear" filename="gazebo_ros_ray_sensor.so">
                <frame_name>camera_back</frame_name>
                <image_topic_name>/camera_front/image_raw</image_topic_name>
                <camera_info_topic_name>/camera_front/camera_info</camera_info_topic_name>
            </plugin>
        </sensor>
  </gazebo>

    <gazebo reference="lidar_front">
        <sensor name="front_lidar_sensor" type="gpu_ray">
          <pose>0 0 0 0 0 0</pose>
          <visualize>true</visualize>
          <update_rate>10.0</update_rate>
          <ray>
            <scan>
              <horizontal>
                <samples>720</samples>
                <resolution>1</resolution>
                <min_angle>-1.047</min_angle> 
                <max_angle>1.047</max_angle>  
              </horizontal>
            </scan>
            <range>
              <min>0.1</min>
              <max>10.0</max>
              <resolution>0.01</resolution>
            </range>
            <noise>
              <type>gaussian</type>
              <mean>0.0</mean>
              <stddev>0.01</stddev>
            </noise>
          </ray>
          <plugin name="front_lidar_plugin" filename="libgazebo_ros_ray_sensor.so">
            <topicName>/lidar_front/scan</topicName>
            <frameName>lidar_front</frameName>
            <update_rate>10.0 </update_rate>
          </plugin>
        </sensor>
    </gazebo>
    <gazebo reference="lidar_back">
        <sensor name="rear_lidar_sensor" type="gpu_ray">
          <pose>0 0 0 0 0 0</pose>
          <visualize>true</visualize>
          <update_rate>10.0</update_rate>
          <ray>
            <scan>
              <horizontal>
                <samples>720</samples>
                <resolution>1</resolution>
                <min_angle>-1.047</min_angle> 
                <max_angle>1.047</max_angle>  
              </horizontal>
            </scan>
            <range>
              <min>0.1</min>
              <max>10.0</max>
              <resolution>0.01</resolution>
            </range>
            <noise>
              <type>gaussian</type>
              <mean>0.0</mean>
              <stddev>0.01</stddev>
            </noise>
          </ray>
          <plugin name="rear_lidar_plugin" filename="libgazebo_ros_ray_sensor.so">
            <topicName>/lidar_back/scan</topicName>
            <frameName>lidar_back</frameName>
            <updateRate>10.0 </updateRate>
          </plugin>
        </sensor>
    </gazebo>   

    <gazebo>
      <plugin name="diff_drive_controller" filename="libgazebo_ros_diff_drive.so">
        <update_rate>50</update_rate>
        <left_joint>joint_wheel_left_0</left_joint>        
        <right_joint>joint_wheel_right_0</right_joint>
        <wheel_separation>0.9</wheel_separation>        
        <wheel_diameter>0.2</wheel_diameter>  
        <publish_odom>true</publish_odom>
        <publish_odom_tf>true</publish_odom_tf>
        <publish_wheel_tf>true</publish_wheel_tf>
        <odometry_topic>odom</odometry_topic>
        <odometry_frame>odom</odometry_frame>
        <robot_base_frame>base_footprint</robot_base_frame>
      </plugin>
    </gazebo>

 </robot>
